<?xml version="1.0"?>
<robot name="three_wheel_bot">

  <!-- == Materials == -->
  <material name="blue"><color rgba="0.1 0.1 0.8 1"/></material>
  <material name="black"><color rgba="0 0 0 1"/></material>
  <material name="gray"><color rgba="0.6 0.6 0.6 1"/></material>

  <!-- =========================================================
       Root (no inertia) -> base_link (has inertia & geometry)
       This avoids robot_state_publisher root-inertia warnings
       ========================================================= -->
  <link name="base_footprint"/>
  <joint name="base_footprint_to_base_link" type="fixed">
    <parent link="base_footprint"/>
    <child link="base_link"/>
    <origin xyz="0 0 0" rpy="0 0 0"/>
  </joint>

  <!-- ================== BASE ================== -->
  <!-- Base frame at z=0. The chassis box is centered at z=0.10
       so its bottom is 0.05 m above ground. Wheels are at z=0.0 -->
  <link name="base_link">
    <visual>
      <origin xyz="0 0 0.10" rpy="0 0 0"/>
      <geometry><box size="0.6 0.4 0.20"/></geometry>
      <material name="blue"/>
    </visual>
    <collision>
      <origin xyz="0 0 0.10" rpy="0 0 0"/>
      <geometry><box size="0.45 0.34 0.20"/></geometry>
    </collision>
    <inertial>
      <origin xyz="0 0 0.10" rpy="0 0 0"/>
      <mass value="8.0"/>
      <inertia ixx="0.20" ixy="0.0" ixz="0.0"
               iyy="0.22" iyz="0.0" izz="0.35"/>
    </inertial>
  </link>

  <!-- ================== DRIVE WHEELS (left/right) ================== -->
  <!-- Wheel radius = 0.08, thickness = 0.04
       Place joints at z=0 so wheel bottom touches ground (z=0 - 0.08) -->
  <link name="left_wheel_link">
    <visual>
      <!-- cylinder axis along Y: rotate +90deg about X -->
      <origin xyz="0 0 0" rpy="1.5708 0 0"/>
      <geometry><cylinder radius="0.08" length="0.04"/></geometry>
      <material name="black"/>
    </visual>
    <collision>
      <origin xyz="0 0 0" rpy="1.5708 0 0"/>
      <geometry><cylinder radius="0.08" length="0.04"/></geometry>
    </collision>
    <inertial>
      <origin xyz="0 0 0" rpy="0 0 0"/>
      <mass value="1.0"/>
      <inertia ixx="0.01" ixy="0.0" ixz="0.0"
               iyy="0.01" iyz="0.0" izz="0.01"/>
    </inertial>
  </link>
  <joint name="left_wheel_joint" type="continuous">
    <parent link="base_link"/>
    <child link="left_wheel_link"/>
    <origin xyz="-0.2 0.21 0.00" rpy="0 0 0"/>
    <axis xyz="0 1 0"/>
  </joint>

  <link name="right_wheel_link">
    <visual>
      <origin xyz="0 0 0" rpy="1.5708 0 0"/>
      <geometry><cylinder radius="0.08" length="0.04"/></geometry>
      <material name="black"/>
    </visual>
    <collision>
      <origin xyz="0 0 0" rpy="1.5708 0 0"/>
      <geometry><cylinder radius="0.08" length="0.04"/></geometry>
    </collision>
    <inertial>
      <origin xyz="0 0 0" rpy="0 0 0"/>
      <mass value="1.0"/>
      <inertia ixx="0.01" ixy="0.0" ixz="0.0"
               iyy="0.01" iyz="0.0" izz="0.01"/>
    </inertial>
  </link>
  <joint name="right_wheel_joint" type="continuous">
    <parent link="base_link"/>
    <child link="right_wheel_link"/>
    <origin xyz="-0.2 -0.21 0.00" rpy="0 0 0"/>
    <axis xyz="0 1 0"/>
  </joint>

  <!-- ================== CASTER (passive) ================== -->
  <!-- Use a small sphere to approximate an omni caster—stable & simple -->
  <!-- Passive Caster -->
  <!-- Passive caster (ball) -->
  <!-- ================== CASTER (passive) ================== -->
  <!-- <link name="rear_caster">
    <visual>
      <geometry>
        <sphere radius="0.04"/>
      </geometry>
      <material name="gray"/>
    </visual>
    <collision>
      <geometry>
        <sphere radius="0.04"/>
      </geometry>
    </collision>
    <inertial>
      <mass value="0.1"/>
      <inertia ixx="0.0001" ixy="0.0" ixz="0.0"
              iyy="0.0001" iyz="0.0"
              izz="0.0001"/>
    </inertial>
  </link>

  <joint name="rear_caster_joint" type="fixed">
    <parent link="base_link"/>
    <child link="rear_caster"/>

    <origin xyz="0.25 0.0 0.04" rpy="0 0 0"/>
  </joint>

  <gazebo reference="rear_caster">
    <mu1>0.6</mu1>
    <mu2>0.6</mu2>
  </gazebo> -->

<!-- ================= FRONT LEFT WHEEL ================= -->
<link name="front_left_wheel">
  <visual>
    <origin xyz="0 0 0" rpy="0 0 0"/>
    <geometry>
      <cylinder radius="0.08" length="0.04"/>
    </geometry>
    <material name="black"/>
  </visual>
  <collision>
    <origin xyz="0 0 0" rpy="0 0 0"/>
    <geometry>
      <cylinder radius="0.08" length="0.04"/>
    </geometry>
  </collision>
  <inertial>
    <mass value="0.5"/>
    <inertia ixx="0.001" ixy="0.0" ixz="0.0" iyy="0.001" iyz="0.0" izz="0.001"/>
  </inertial>
</link>

<!-- Steering joint (yaw) -->
<joint name="front_left_steering_joint" type="revolute">
  <parent link="base_link"/>
  <child link="front_left_wheel"/>
  <origin xyz="0.3 0.2 0.05" rpy="0 0 0"/>
  <axis xyz="0 0 1"/>
  <limit lower="-0.6" upper="0.6" effort="20" velocity="1.0"/>
</joint>

<!-- Rolling joint (wheel rotation) -->
<joint name="front_left_wheel_roll_joint" type="continuous">
  <parent link="front_left_wheel"/>
  <child link="front_left_wheel"/> <!-- rotate the same wheel link -->
  <origin xyz="0 0 0" rpy="0 1.5708 0"/>
  <axis xyz="0 1 0"/>
</joint>

<!-- ================= FRONT RIGHT WHEEL ================= -->
<link name="front_right_wheel">
  <visual>
    <origin xyz="0 0 0" rpy="0 0 0"/>
    <geometry>
      <cylinder radius="0.08" length="0.04"/>
    </geometry>
    <material name="black"/>
  </visual>
  <collision>
    <origin xyz="0 0 0" rpy="0 0 0"/>
    <geometry>
      <cylinder radius="0.08" length="0.04"/>
    </geometry>
  </collision>
  <inertial>
    <mass value="0.5"/>
    <inertia ixx="0.001" ixy="0.0" ixz="0.0" iyy="0.001" iyz="0.0" izz="0.001"/>
  </inertial>
</link>

<!-- Steering joint -->
<joint name="front_right_steering_joint" type="revolute">
  <parent link="base_link"/>
  <child link="front_right_wheel"/>
  <origin xyz="0.3 -0.2 0.05" rpy="0 0 0"/>
  <axis xyz="0 0 1"/>
  <limit lower="-0.6" upper="0.6" effort="20" velocity="1.0"/>
</joint>

<!-- Rolling joint (wheel rotation) -->
<joint name="front_right_wheel_roll_joint" type="continuous">
  <parent link="front_right_wheel"/>
  <child link="front_right_wheel"/> <!-- rotate the same wheel link -->
  <origin xyz="0 0 0" rpy="0 1.5708 0"/>
  <axis xyz="0 1 0"/>
</joint>



  <!-- ================== TRAY POST + TRAY (optional visuals) ================== -->
  <link name="tray_post">
    <visual>
      <origin xyz="0 0 0.25" rpy="0 0 0"/>
      <geometry><cylinder radius="0.03" length="0.5"/></geometry>
      <material name="gray"/>
    </visual>
    <collision>
      <origin xyz="0 0 0.25" rpy="0 0 0"/>
      <geometry><cylinder radius="0.03" length="0.5"/></geometry>
    </collision>  
    <inertial>
      <origin xyz="0 0 0.25" rpy="0 0 0"/>
      <mass value="1.0"/>
      <inertia ixx="0.003" ixy="0.0" ixz="0.0"
               iyy="0.003" iyz="0.0" izz="0.003"/>
    </inertial>
  </link>
  <joint name="tray_post_joint" type="fixed">
    <parent link="base_link"/>
    <child link="tray_post"/>
    <origin xyz="0 0 0.20" rpy="0 0 0"/>
  </joint>

  <link name="tray_link">
    <visual>
      <origin xyz="0 0 0.02" rpy="0 0 0"/>
      <geometry><box size="0.40 0.30 0.04"/></geometry>
      <material name="gray"/>
    </visual>
    <collision>
      <origin xyz="0 0 0.02" rpy="0 0 0"/>
      <geometry><box size="0.40 0.30 0.04"/></geometry>
    </collision>
    <inertial>
      <origin xyz="0 0 0.02" rpy="0 0 0"/>
      <mass value="0.8"/>
      <inertia ixx="0.004" ixy="0.0" ixz="0.0"
               iyy="0.006" iyz="0.0" izz="0.009"/>
    </inertial>
  </link>
  <joint name="tray_joint" type="fixed">
    <parent link="tray_post"/>
    <child link="tray_link"/>
    <origin xyz="0 0 0.50" rpy="0 0 0"/>
  </joint>

  <!-- ================== LIDAR (simple 2D) ================== -->
  <link name="lidar_link">
    <visual>
      <origin xyz="0.20 0 0.22" rpy="0 0 0"/>
      <geometry><cylinder radius="0.05" length="0.05"/></geometry>
      <material name="gray"/>
    </visual>
    <collision>
      <origin xyz="0.20 0 0.22" rpy="0 0 0"/>
      <geometry><cylinder radius="0.05" length="0.05"/></geometry>
    </collision>
    <inertial>
      <origin xyz="0.20 0 0.22" rpy="0 0 0"/>
      <mass value="0.5"/>
      <inertia ixx="0.001" ixy="0.0" ixz="0.0"
               iyy="0.001" iyz="0.0" izz="0.001"/>
    </inertial>
  </link>
  <joint name="lidar_joint" type="fixed">
    <parent link="base_link"/>
    <child link="lidar_link"/>
    <origin xyz="0 0 0" rpy="0 0 0"/>
  </joint>

  <!-- ================== Gazebo Plugins & Params ================== -->
  <!-- Diff drive uses only the left/right wheel joints -->
  <gazebo>
    <plugin name="diff_drive" filename="libgazebo_ros_diff_drive.so">
      <ros>
        <namespace>/</namespace>
        <remapping>cmd_vel:=cmd_vel</remapping>
      </ros>
      <update_rate>30</update_rate>
      <left_joint>left_wheel_joint</left_joint>
      <right_joint>right_wheel_joint</right_joint>
      <wheel_separation>0.34</wheel_separation>   <!-- 0.17 - (-0.17) -->
      <wheel_diameter>0.16</wheel_diameter>       <!-- 2 * 0.08 -->
      <publish_odom>true</publish_odom>
      <publish_odom_tf>true</publish_odom_tf>
      <odometry_frame>odom</odometry_frame>
      <robot_base_frame>base_link</robot_base_frame>
      <command_timeout>1.0</command_timeout>
    </plugin>
  </gazebo>

  <!-- Give the caster a bit more grip; keep wheels grippy too -->
  <gazebo reference="left_wheel_link"><mu1>1.0</mu1><mu2>1.0</mu2></gazebo>
  <gazebo reference="right_wheel_link"><mu1>1.0</mu1><mu2>1.0</mu2></gazebo>
  <gazebo reference="caster_link"><mu1>0.6</mu1><mu2>0.6</mu2></gazebo>

  <!-- Lidar sensor on lidar_link -->
  <gazebo reference="lidar_link">
    <sensor type="ray" name="lidar">
      <pose>0 0 0 0 0 0</pose>
      <visualize>false</visualize>
      <update_rate>10</update_rate>
      <ray>
        <scan>
          <horizontal>
            <samples>720</samples>
            <resolution>1</resolution>
            <min_angle>-3.14159</min_angle>
            <max_angle>3.14159</max_angle>
          </horizontal>
        </scan>
        <range>
          <min>0.12</min>
          <max>12.0</max>
          <resolution>0.01</resolution>
        </range>
        <noise>
          <type>gaussian</type>
          <mean>0.0</mean>
          <stddev>0.01</stddev>
        </noise>
      </ray>
      <plugin name="gazebo_ros_laser" filename="libgazebo_ros_ray_sensor.so">
        <ros><remapping>~/out:=scan</remapping></ros>
        <output_type>sensor_msgs/LaserScan</output_type>
        <frame_name>lidar_link</frame_name>
      </plugin>
    </sensor>
  </gazebo>

</robot>
